[2024-09-20T22:13:00.591+0000] {local_task_job_runner.py:123} INFO - ::group::Pre task execution logs
[2024-09-20T22:13:00.618+0000] {taskinstance.py:2612} INFO - Dependencies all met for dep_context=non-requeueable deps ti=<TaskInstance: Read_data_and_move_data.Move_data_to_processed_folder scheduled__2024-09-20T11:50:00+00:00 [queued]>
[2024-09-20T22:13:00.631+0000] {taskinstance.py:2612} INFO - Dependencies all met for dep_context=requeueable deps ti=<TaskInstance: Read_data_and_move_data.Move_data_to_processed_folder scheduled__2024-09-20T11:50:00+00:00 [queued]>
[2024-09-20T22:13:00.632+0000] {taskinstance.py:2865} INFO - Starting attempt 1 of 1
[2024-09-20T22:13:00.658+0000] {taskinstance.py:2888} INFO - Executing <Task(PythonOperator): Move_data_to_processed_folder> on 2024-09-20 11:50:00+00:00
[2024-09-20T22:13:00.679+0000] {warnings.py:112} WARNING - /home/***/.local/lib/python3.12/site-packages/***/task/task_runner/standard_task_runner.py:70: DeprecationWarning: This process (pid=63) is multi-threaded, use of fork() may lead to deadlocks in the child.
  pid = os.fork()

[2024-09-20T22:13:00.680+0000] {standard_task_runner.py:104} INFO - Running: ['***', 'tasks', 'run', 'Read_data_and_move_data', 'Move_data_to_processed_folder', 'scheduled__2024-09-20T11:50:00+00:00', '--job-id', '53', '--raw', '--subdir', 'DAGS_FOLDER/data_ingestion.py', '--cfg-path', '/tmp/tmps7ajx7zh']
[2024-09-20T22:13:00.683+0000] {standard_task_runner.py:72} INFO - Started process 67 to run task
[2024-09-20T22:13:00.684+0000] {standard_task_runner.py:105} INFO - Job 53: Subtask Move_data_to_processed_folder
[2024-09-20T22:13:00.826+0000] {task_command.py:467} INFO - Running <TaskInstance: Read_data_and_move_data.Move_data_to_processed_folder scheduled__2024-09-20T11:50:00+00:00 [running]> on host 34d62e1e9714
[2024-09-20T22:13:01.020+0000] {taskinstance.py:3131} INFO - Exporting env vars: AIRFLOW_CTX_DAG_OWNER='***' AIRFLOW_CTX_DAG_ID='Read_data_and_move_data' AIRFLOW_CTX_TASK_ID='Move_data_to_processed_folder' AIRFLOW_CTX_EXECUTION_DATE='2024-09-20T11:50:00+00:00' AIRFLOW_CTX_TRY_NUMBER='1' AIRFLOW_CTX_DAG_RUN_ID='scheduled__2024-09-20T11:50:00+00:00'
[2024-09-20T22:13:01.023+0000] {logging_mixin.py:190} INFO - Task instance is in running state
[2024-09-20T22:13:01.024+0000] {logging_mixin.py:190} INFO -  Previous state of the Task instance: queued
[2024-09-20T22:13:01.025+0000] {logging_mixin.py:190} INFO - Current task name:Move_data_to_processed_folder state:running start_date:2024-09-20 22:13:00.619418+00:00
[2024-09-20T22:13:01.027+0000] {logging_mixin.py:190} INFO - Dag name:Read_data_and_move_data and current dag run status:running
[2024-09-20T22:13:01.028+0000] {taskinstance.py:731} INFO - ::endgroup::
[2024-09-20T22:13:01.080+0000] {taskinstance.py:3310} ERROR - Task failed with exception
Traceback (most recent call last):
  File "/usr/local/lib/python3.12/shutil.py", line 847, in move
    os.rename(src, real_dst)
OSError: [Errno 18] Invalid cross-device link: '/opt/airflow/raw_data/heart4.csv' -> '/opt/airflow/processed_data/heart4.csv'

During handling of the above exception, another exception occurred:

Traceback (most recent call last):
  File "/home/airflow/.local/lib/python3.12/site-packages/airflow/models/taskinstance.py", line 767, in _execute_task
    result = _execute_callable(context=context, **execute_callable_kwargs)
             ^^^^^^^^^^^^^^^^^^^^^^^^^^^^^^^^^^^^^^^^^^^^^^^^^^^^^^^^^^^^^
  File "/home/airflow/.local/lib/python3.12/site-packages/airflow/models/taskinstance.py", line 733, in _execute_callable
    return ExecutionCallableRunner(
           ^^^^^^^^^^^^^^^^^^^^^^^^
  File "/home/airflow/.local/lib/python3.12/site-packages/airflow/utils/operator_helpers.py", line 252, in run
    return self.func(*args, **kwargs)
           ^^^^^^^^^^^^^^^^^^^^^^^^^^
  File "/home/airflow/.local/lib/python3.12/site-packages/airflow/models/baseoperator.py", line 406, in wrapper
    return func(self, *args, **kwargs)
           ^^^^^^^^^^^^^^^^^^^^^^^^^^^
  File "/home/airflow/.local/lib/python3.12/site-packages/airflow/operators/python.py", line 238, in execute
    return_value = self.execute_callable()
                   ^^^^^^^^^^^^^^^^^^^^^^^
  File "/home/airflow/.local/lib/python3.12/site-packages/airflow/operators/python.py", line 256, in execute_callable
    return runner.run(*self.op_args, **self.op_kwargs)
           ^^^^^^^^^^^^^^^^^^^^^^^^^^^^^^^^^^^^^^^^^^^
  File "/home/airflow/.local/lib/python3.12/site-packages/airflow/utils/operator_helpers.py", line 252, in run
    return self.func(*args, **kwargs)
           ^^^^^^^^^^^^^^^^^^^^^^^^^^
  File "/opt/airflow/dags/data_ingestion.py", line 33, in save_data
    shutil.move(file_path, destination_path)
  File "/usr/local/lib/python3.12/shutil.py", line 868, in move
    os.unlink(src)
FileNotFoundError: [Errno 2] No such file or directory: '/opt/airflow/raw_data/heart4.csv'
[2024-09-20T22:13:01.104+0000] {logging_mixin.py:190} INFO - Task instance in failure state
[2024-09-20T22:13:01.105+0000] {logging_mixin.py:190} INFO - Task start:2024-09-20 22:13:00.619418+00:00 end:2024-09-20 22:13:01.102932+00:00 duration:0.483514
[2024-09-20T22:13:01.106+0000] {logging_mixin.py:190} INFO - Task:<Task(PythonOperator): Move_data_to_processed_folder> dag:<DAG: Read_data_and_move_data> dagrun:<DagRun Read_data_and_move_data @ 2024-09-20 11:50:00+00:00: scheduled__2024-09-20T11:50:00+00:00, state:running, queued_at: 2024-09-20 22:12:31.876082+00:00. externally triggered: False>
[2024-09-20T22:13:01.107+0000] {logging_mixin.py:190} INFO - Failure caused by [Errno 2] No such file or directory: '/opt/***/raw_data/heart4.csv'
[2024-09-20T22:13:01.107+0000] {taskinstance.py:1225} INFO - Marking task as FAILED. dag_id=Read_data_and_move_data, task_id=Move_data_to_processed_folder, run_id=scheduled__2024-09-20T11:50:00+00:00, execution_date=20240920T115000, start_date=20240920T221300, end_date=20240920T221301
[2024-09-20T22:13:01.131+0000] {taskinstance.py:340} INFO - ::group::Post task execution logs
[2024-09-20T22:13:01.132+0000] {standard_task_runner.py:124} ERROR - Failed to execute job 53 for task Move_data_to_processed_folder ([Errno 2] No such file or directory: '/opt/airflow/raw_data/heart4.csv'; 67)
Traceback (most recent call last):
  File "/usr/local/lib/python3.12/shutil.py", line 847, in move
    os.rename(src, real_dst)
OSError: [Errno 18] Invalid cross-device link: '/opt/airflow/raw_data/heart4.csv' -> '/opt/airflow/processed_data/heart4.csv'

During handling of the above exception, another exception occurred:

Traceback (most recent call last):
  File "/home/airflow/.local/lib/python3.12/site-packages/airflow/task/task_runner/standard_task_runner.py", line 117, in _start_by_fork
    ret = args.func(args, dag=self.dag)
          ^^^^^^^^^^^^^^^^^^^^^^^^^^^^^
  File "/home/airflow/.local/lib/python3.12/site-packages/airflow/cli/cli_config.py", line 49, in command
    return func(*args, **kwargs)
           ^^^^^^^^^^^^^^^^^^^^^
  File "/home/airflow/.local/lib/python3.12/site-packages/airflow/utils/cli.py", line 115, in wrapper
    return f(*args, **kwargs)
           ^^^^^^^^^^^^^^^^^^
  File "/home/airflow/.local/lib/python3.12/site-packages/airflow/cli/commands/task_command.py", line 483, in task_run
    task_return_code = _run_task_by_selected_method(args, _dag, ti)
                       ^^^^^^^^^^^^^^^^^^^^^^^^^^^^^^^^^^^^^^^^^^^^
  File "/home/airflow/.local/lib/python3.12/site-packages/airflow/cli/commands/task_command.py", line 256, in _run_task_by_selected_method
    return _run_raw_task(args, ti)
           ^^^^^^^^^^^^^^^^^^^^^^^
  File "/home/airflow/.local/lib/python3.12/site-packages/airflow/cli/commands/task_command.py", line 341, in _run_raw_task
    return ti._run_raw_task(
           ^^^^^^^^^^^^^^^^^
  File "/home/airflow/.local/lib/python3.12/site-packages/airflow/utils/session.py", line 97, in wrapper
    return func(*args, session=session, **kwargs)
           ^^^^^^^^^^^^^^^^^^^^^^^^^^^^^^^^^^^^^^
  File "/home/airflow/.local/lib/python3.12/site-packages/airflow/models/taskinstance.py", line 3004, in _run_raw_task
    return _run_raw_task(
           ^^^^^^^^^^^^^^
  File "/home/airflow/.local/lib/python3.12/site-packages/airflow/models/taskinstance.py", line 273, in _run_raw_task
    TaskInstance._execute_task_with_callbacks(
  File "/home/airflow/.local/lib/python3.12/site-packages/airflow/models/taskinstance.py", line 3158, in _execute_task_with_callbacks
    result = self._execute_task(context, task_orig)
             ^^^^^^^^^^^^^^^^^^^^^^^^^^^^^^^^^^^^^^
  File "/home/airflow/.local/lib/python3.12/site-packages/airflow/models/taskinstance.py", line 3182, in _execute_task
    return _execute_task(self, context, task_orig)
           ^^^^^^^^^^^^^^^^^^^^^^^^^^^^^^^^^^^^^^^
  File "/home/airflow/.local/lib/python3.12/site-packages/airflow/models/taskinstance.py", line 767, in _execute_task
    result = _execute_callable(context=context, **execute_callable_kwargs)
             ^^^^^^^^^^^^^^^^^^^^^^^^^^^^^^^^^^^^^^^^^^^^^^^^^^^^^^^^^^^^^
  File "/home/airflow/.local/lib/python3.12/site-packages/airflow/models/taskinstance.py", line 733, in _execute_callable
    return ExecutionCallableRunner(
           ^^^^^^^^^^^^^^^^^^^^^^^^
  File "/home/airflow/.local/lib/python3.12/site-packages/airflow/utils/operator_helpers.py", line 252, in run
    return self.func(*args, **kwargs)
           ^^^^^^^^^^^^^^^^^^^^^^^^^^
  File "/home/airflow/.local/lib/python3.12/site-packages/airflow/models/baseoperator.py", line 406, in wrapper
    return func(self, *args, **kwargs)
           ^^^^^^^^^^^^^^^^^^^^^^^^^^^
  File "/home/airflow/.local/lib/python3.12/site-packages/airflow/operators/python.py", line 238, in execute
    return_value = self.execute_callable()
                   ^^^^^^^^^^^^^^^^^^^^^^^
  File "/home/airflow/.local/lib/python3.12/site-packages/airflow/operators/python.py", line 256, in execute_callable
    return runner.run(*self.op_args, **self.op_kwargs)
           ^^^^^^^^^^^^^^^^^^^^^^^^^^^^^^^^^^^^^^^^^^^
  File "/home/airflow/.local/lib/python3.12/site-packages/airflow/utils/operator_helpers.py", line 252, in run
    return self.func(*args, **kwargs)
           ^^^^^^^^^^^^^^^^^^^^^^^^^^
  File "/opt/airflow/dags/data_ingestion.py", line 33, in save_data
    shutil.move(file_path, destination_path)
  File "/usr/local/lib/python3.12/shutil.py", line 868, in move
    os.unlink(src)
FileNotFoundError: [Errno 2] No such file or directory: '/opt/airflow/raw_data/heart4.csv'
[2024-09-20T22:13:01.157+0000] {local_task_job_runner.py:266} INFO - Task exited with return code 1
[2024-09-20T22:13:01.182+0000] {taskinstance.py:3900} INFO - 0 downstream tasks scheduled from follow-on schedule check
[2024-09-20T22:13:01.188+0000] {local_task_job_runner.py:245} INFO - ::endgroup::
