[2024-09-20T23:05:19.475+0000] {local_task_job_runner.py:123} INFO - ::group::Pre task execution logs
[2024-09-20T23:05:19.497+0000] {taskinstance.py:2612} INFO - Dependencies all met for dep_context=non-requeueable deps ti=<TaskInstance: Read_data_and_move_data.Read_dataset_files manual__2024-09-20T23:05:14.411738+00:00 [queued]>
[2024-09-20T23:05:19.513+0000] {taskinstance.py:2612} INFO - Dependencies all met for dep_context=requeueable deps ti=<TaskInstance: Read_data_and_move_data.Read_dataset_files manual__2024-09-20T23:05:14.411738+00:00 [queued]>
[2024-09-20T23:05:19.514+0000] {taskinstance.py:2865} INFO - Starting attempt 1 of 1
[2024-09-20T23:05:19.539+0000] {taskinstance.py:2888} INFO - Executing <Task(PythonOperator): Read_dataset_files> on 2024-09-20 23:05:14.411738+00:00
[2024-09-20T23:05:19.550+0000] {warnings.py:112} WARNING - /home/***/.local/lib/python3.12/site-packages/***/task/task_runner/standard_task_runner.py:70: DeprecationWarning: This process (pid=139) is multi-threaded, use of fork() may lead to deadlocks in the child.
  pid = os.fork()

[2024-09-20T23:05:19.551+0000] {standard_task_runner.py:104} INFO - Running: ['***', 'tasks', 'run', 'Read_data_and_move_data', 'Read_dataset_files', 'manual__2024-09-20T23:05:14.411738+00:00', '--job-id', '84', '--raw', '--subdir', 'DAGS_FOLDER/data_ingestion.py', '--cfg-path', '/tmp/tmpcpefkzjm']
[2024-09-20T23:05:19.553+0000] {standard_task_runner.py:72} INFO - Started process 141 to run task
[2024-09-20T23:05:19.553+0000] {standard_task_runner.py:105} INFO - Job 84: Subtask Read_dataset_files
[2024-09-20T23:05:19.619+0000] {task_command.py:467} INFO - Running <TaskInstance: Read_data_and_move_data.Read_dataset_files manual__2024-09-20T23:05:14.411738+00:00 [running]> on host 31cbd40558b4
[2024-09-20T23:05:19.742+0000] {taskinstance.py:3131} INFO - Exporting env vars: AIRFLOW_CTX_DAG_OWNER='***' AIRFLOW_CTX_DAG_ID='Read_data_and_move_data' AIRFLOW_CTX_TASK_ID='Read_dataset_files' AIRFLOW_CTX_EXECUTION_DATE='2024-09-20T23:05:14.411738+00:00' AIRFLOW_CTX_TRY_NUMBER='1' AIRFLOW_CTX_DAG_RUN_ID='manual__2024-09-20T23:05:14.411738+00:00'
[2024-09-20T23:05:19.743+0000] {logging_mixin.py:190} INFO - Task instance is in running state
[2024-09-20T23:05:19.744+0000] {logging_mixin.py:190} INFO -  Previous state of the Task instance: queued
[2024-09-20T23:05:19.745+0000] {logging_mixin.py:190} INFO - Current task name:Read_dataset_files state:running start_date:2024-09-20 23:05:19.498495+00:00
[2024-09-20T23:05:19.746+0000] {logging_mixin.py:190} INFO - Dag name:Read_data_and_move_data and current dag run status:running
[2024-09-20T23:05:19.747+0000] {taskinstance.py:731} INFO - ::endgroup::
[2024-09-20T23:05:19.751+0000] {taskinstance.py:3310} ERROR - Task failed with exception
Traceback (most recent call last):
  File "/home/airflow/.local/lib/python3.12/site-packages/airflow/models/taskinstance.py", line 767, in _execute_task
    result = _execute_callable(context=context, **execute_callable_kwargs)
             ^^^^^^^^^^^^^^^^^^^^^^^^^^^^^^^^^^^^^^^^^^^^^^^^^^^^^^^^^^^^^
  File "/home/airflow/.local/lib/python3.12/site-packages/airflow/models/taskinstance.py", line 733, in _execute_callable
    return ExecutionCallableRunner(
           ^^^^^^^^^^^^^^^^^^^^^^^^
  File "/home/airflow/.local/lib/python3.12/site-packages/airflow/utils/operator_helpers.py", line 252, in run
    return self.func(*args, **kwargs)
           ^^^^^^^^^^^^^^^^^^^^^^^^^^
  File "/home/airflow/.local/lib/python3.12/site-packages/airflow/models/baseoperator.py", line 406, in wrapper
    return func(self, *args, **kwargs)
           ^^^^^^^^^^^^^^^^^^^^^^^^^^^
  File "/home/airflow/.local/lib/python3.12/site-packages/airflow/operators/python.py", line 238, in execute
    return_value = self.execute_callable()
                   ^^^^^^^^^^^^^^^^^^^^^^^
  File "/home/airflow/.local/lib/python3.12/site-packages/airflow/operators/python.py", line 256, in execute_callable
    return runner.run(*self.op_args, **self.op_kwargs)
           ^^^^^^^^^^^^^^^^^^^^^^^^^^^^^^^^^^^^^^^^^^^
  File "/home/airflow/.local/lib/python3.12/site-packages/airflow/utils/operator_helpers.py", line 252, in run
    return self.func(*args, **kwargs)
           ^^^^^^^^^^^^^^^^^^^^^^^^^^
  File "/opt/airflow/dags/data_ingestion.py", line 14, in read_data
    raise ValueError("No files in the folder")
ValueError: No files in the folder
[2024-09-20T23:05:19.772+0000] {logging_mixin.py:190} INFO - Task instance in failure state
[2024-09-20T23:05:19.774+0000] {logging_mixin.py:190} INFO - Task start:2024-09-20 23:05:19.498495+00:00 end:2024-09-20 23:05:19.772277+00:00 duration:0.273782
[2024-09-20T23:05:19.774+0000] {logging_mixin.py:190} INFO - Task:<Task(PythonOperator): Read_dataset_files> dag:<DAG: Read_data_and_move_data> dagrun:<DagRun Read_data_and_move_data @ 2024-09-20 23:05:14.411738+00:00: manual__2024-09-20T23:05:14.411738+00:00, state:running, queued_at: 2024-09-20 23:05:14.704734+00:00. externally triggered: True>
[2024-09-20T23:05:19.775+0000] {logging_mixin.py:190} INFO - Failure caused by No files in the folder
[2024-09-20T23:05:19.776+0000] {taskinstance.py:1225} INFO - Marking task as FAILED. dag_id=Read_data_and_move_data, task_id=Read_dataset_files, run_id=manual__2024-09-20T23:05:14.411738+00:00, execution_date=20240920T230514, start_date=20240920T230519, end_date=20240920T230519
[2024-09-20T23:05:19.797+0000] {taskinstance.py:340} INFO - ::group::Post task execution logs
[2024-09-20T23:05:19.798+0000] {standard_task_runner.py:124} ERROR - Failed to execute job 84 for task Read_dataset_files (No files in the folder; 141)
Traceback (most recent call last):
  File "/home/airflow/.local/lib/python3.12/site-packages/airflow/task/task_runner/standard_task_runner.py", line 117, in _start_by_fork
    ret = args.func(args, dag=self.dag)
          ^^^^^^^^^^^^^^^^^^^^^^^^^^^^^
  File "/home/airflow/.local/lib/python3.12/site-packages/airflow/cli/cli_config.py", line 49, in command
    return func(*args, **kwargs)
           ^^^^^^^^^^^^^^^^^^^^^
  File "/home/airflow/.local/lib/python3.12/site-packages/airflow/utils/cli.py", line 115, in wrapper
    return f(*args, **kwargs)
           ^^^^^^^^^^^^^^^^^^
  File "/home/airflow/.local/lib/python3.12/site-packages/airflow/cli/commands/task_command.py", line 483, in task_run
    task_return_code = _run_task_by_selected_method(args, _dag, ti)
                       ^^^^^^^^^^^^^^^^^^^^^^^^^^^^^^^^^^^^^^^^^^^^
  File "/home/airflow/.local/lib/python3.12/site-packages/airflow/cli/commands/task_command.py", line 256, in _run_task_by_selected_method
    return _run_raw_task(args, ti)
           ^^^^^^^^^^^^^^^^^^^^^^^
  File "/home/airflow/.local/lib/python3.12/site-packages/airflow/cli/commands/task_command.py", line 341, in _run_raw_task
    return ti._run_raw_task(
           ^^^^^^^^^^^^^^^^^
  File "/home/airflow/.local/lib/python3.12/site-packages/airflow/utils/session.py", line 97, in wrapper
    return func(*args, session=session, **kwargs)
           ^^^^^^^^^^^^^^^^^^^^^^^^^^^^^^^^^^^^^^
  File "/home/airflow/.local/lib/python3.12/site-packages/airflow/models/taskinstance.py", line 3004, in _run_raw_task
    return _run_raw_task(
           ^^^^^^^^^^^^^^
  File "/home/airflow/.local/lib/python3.12/site-packages/airflow/models/taskinstance.py", line 273, in _run_raw_task
    TaskInstance._execute_task_with_callbacks(
  File "/home/airflow/.local/lib/python3.12/site-packages/airflow/models/taskinstance.py", line 3158, in _execute_task_with_callbacks
    result = self._execute_task(context, task_orig)
             ^^^^^^^^^^^^^^^^^^^^^^^^^^^^^^^^^^^^^^
  File "/home/airflow/.local/lib/python3.12/site-packages/airflow/models/taskinstance.py", line 3182, in _execute_task
    return _execute_task(self, context, task_orig)
           ^^^^^^^^^^^^^^^^^^^^^^^^^^^^^^^^^^^^^^^
  File "/home/airflow/.local/lib/python3.12/site-packages/airflow/models/taskinstance.py", line 767, in _execute_task
    result = _execute_callable(context=context, **execute_callable_kwargs)
             ^^^^^^^^^^^^^^^^^^^^^^^^^^^^^^^^^^^^^^^^^^^^^^^^^^^^^^^^^^^^^
  File "/home/airflow/.local/lib/python3.12/site-packages/airflow/models/taskinstance.py", line 733, in _execute_callable
    return ExecutionCallableRunner(
           ^^^^^^^^^^^^^^^^^^^^^^^^
  File "/home/airflow/.local/lib/python3.12/site-packages/airflow/utils/operator_helpers.py", line 252, in run
    return self.func(*args, **kwargs)
           ^^^^^^^^^^^^^^^^^^^^^^^^^^
  File "/home/airflow/.local/lib/python3.12/site-packages/airflow/models/baseoperator.py", line 406, in wrapper
    return func(self, *args, **kwargs)
           ^^^^^^^^^^^^^^^^^^^^^^^^^^^
  File "/home/airflow/.local/lib/python3.12/site-packages/airflow/operators/python.py", line 238, in execute
    return_value = self.execute_callable()
                   ^^^^^^^^^^^^^^^^^^^^^^^
  File "/home/airflow/.local/lib/python3.12/site-packages/airflow/operators/python.py", line 256, in execute_callable
    return runner.run(*self.op_args, **self.op_kwargs)
           ^^^^^^^^^^^^^^^^^^^^^^^^^^^^^^^^^^^^^^^^^^^
  File "/home/airflow/.local/lib/python3.12/site-packages/airflow/utils/operator_helpers.py", line 252, in run
    return self.func(*args, **kwargs)
           ^^^^^^^^^^^^^^^^^^^^^^^^^^
  File "/opt/airflow/dags/data_ingestion.py", line 14, in read_data
    raise ValueError("No files in the folder")
ValueError: No files in the folder
[2024-09-20T23:05:19.851+0000] {local_task_job_runner.py:266} INFO - Task exited with return code 1
[2024-09-20T23:05:19.880+0000] {taskinstance.py:3900} INFO - 0 downstream tasks scheduled from follow-on schedule check
[2024-09-20T23:05:19.887+0000] {local_task_job_runner.py:245} INFO - ::endgroup::
