[2024-09-20T23:00:45.271+0000] {local_task_job_runner.py:123} INFO - ::group::Pre task execution logs
[2024-09-20T23:00:45.331+0000] {taskinstance.py:2612} INFO - Dependencies all met for dep_context=non-requeueable deps ti=<TaskInstance: Read_data_and_move_data.Read_dataset_files scheduled__2024-09-20T22:50:00+00:00 [queued]>
[2024-09-20T23:00:45.349+0000] {taskinstance.py:2612} INFO - Dependencies all met for dep_context=requeueable deps ti=<TaskInstance: Read_data_and_move_data.Read_dataset_files scheduled__2024-09-20T22:50:00+00:00 [queued]>
[2024-09-20T23:00:45.351+0000] {taskinstance.py:2865} INFO - Starting attempt 1 of 1
[2024-09-20T23:00:45.372+0000] {taskinstance.py:2888} INFO - Executing <Task(PythonOperator): Read_dataset_files> on 2024-09-20 22:50:00+00:00
[2024-09-20T23:00:45.388+0000] {warnings.py:112} WARNING - /home/***/.local/lib/python3.12/site-packages/***/task/task_runner/standard_task_runner.py:70: DeprecationWarning: This process (pid=54) is multi-threaded, use of fork() may lead to deadlocks in the child.
  pid = os.fork()

[2024-09-20T23:00:45.391+0000] {standard_task_runner.py:72} INFO - Started process 62 to run task
[2024-09-20T23:00:45.390+0000] {standard_task_runner.py:104} INFO - Running: ['***', 'tasks', 'run', 'Read_data_and_move_data', 'Read_dataset_files', 'scheduled__2024-09-20T22:50:00+00:00', '--job-id', '75', '--raw', '--subdir', 'DAGS_FOLDER/data_ingestion.py', '--cfg-path', '/tmp/tmpp7xhtcbu']
[2024-09-20T23:00:45.395+0000] {standard_task_runner.py:105} INFO - Job 75: Subtask Read_dataset_files
[2024-09-20T23:00:45.479+0000] {task_command.py:467} INFO - Running <TaskInstance: Read_data_and_move_data.Read_dataset_files scheduled__2024-09-20T22:50:00+00:00 [running]> on host 31cbd40558b4
[2024-09-20T23:00:45.694+0000] {taskinstance.py:3131} INFO - Exporting env vars: AIRFLOW_CTX_DAG_OWNER='***' AIRFLOW_CTX_DAG_ID='Read_data_and_move_data' AIRFLOW_CTX_TASK_ID='Read_dataset_files' AIRFLOW_CTX_EXECUTION_DATE='2024-09-20T22:50:00+00:00' AIRFLOW_CTX_TRY_NUMBER='1' AIRFLOW_CTX_DAG_RUN_ID='scheduled__2024-09-20T22:50:00+00:00'
[2024-09-20T23:00:45.697+0000] {logging_mixin.py:190} INFO - Task instance is in running state
[2024-09-20T23:00:45.698+0000] {logging_mixin.py:190} INFO -  Previous state of the Task instance: queued
[2024-09-20T23:00:45.699+0000] {logging_mixin.py:190} INFO - Current task name:Read_dataset_files state:running start_date:2024-09-20 23:00:45.333593+00:00
[2024-09-20T23:00:45.700+0000] {logging_mixin.py:190} INFO - Dag name:Read_data_and_move_data and current dag run status:running
[2024-09-20T23:00:45.701+0000] {taskinstance.py:731} INFO - ::endgroup::
[2024-09-20T23:00:45.706+0000] {taskinstance.py:3310} ERROR - Task failed with exception
Traceback (most recent call last):
  File "/home/airflow/.local/lib/python3.12/site-packages/airflow/models/taskinstance.py", line 767, in _execute_task
    result = _execute_callable(context=context, **execute_callable_kwargs)
             ^^^^^^^^^^^^^^^^^^^^^^^^^^^^^^^^^^^^^^^^^^^^^^^^^^^^^^^^^^^^^
  File "/home/airflow/.local/lib/python3.12/site-packages/airflow/models/taskinstance.py", line 733, in _execute_callable
    return ExecutionCallableRunner(
           ^^^^^^^^^^^^^^^^^^^^^^^^
  File "/home/airflow/.local/lib/python3.12/site-packages/airflow/utils/operator_helpers.py", line 252, in run
    return self.func(*args, **kwargs)
           ^^^^^^^^^^^^^^^^^^^^^^^^^^
  File "/home/airflow/.local/lib/python3.12/site-packages/airflow/models/baseoperator.py", line 406, in wrapper
    return func(self, *args, **kwargs)
           ^^^^^^^^^^^^^^^^^^^^^^^^^^^
  File "/home/airflow/.local/lib/python3.12/site-packages/airflow/operators/python.py", line 238, in execute
    return_value = self.execute_callable()
                   ^^^^^^^^^^^^^^^^^^^^^^^
  File "/home/airflow/.local/lib/python3.12/site-packages/airflow/operators/python.py", line 256, in execute_callable
    return runner.run(*self.op_args, **self.op_kwargs)
           ^^^^^^^^^^^^^^^^^^^^^^^^^^^^^^^^^^^^^^^^^^^
  File "/home/airflow/.local/lib/python3.12/site-packages/airflow/utils/operator_helpers.py", line 252, in run
    return self.func(*args, **kwargs)
           ^^^^^^^^^^^^^^^^^^^^^^^^^^
  File "/opt/airflow/dags/data_ingestion.py", line 14, in read_data
    raise ValueError("No files in the folder")
ValueError: No files in the folder
[2024-09-20T23:00:45.750+0000] {logging_mixin.py:190} INFO - Task instance in failure state
[2024-09-20T23:00:45.751+0000] {logging_mixin.py:190} INFO - Task start:2024-09-20 23:00:45.333593+00:00 end:2024-09-20 23:00:45.749724+00:00 duration:0.416131
[2024-09-20T23:00:45.752+0000] {logging_mixin.py:190} INFO - Task:<Task(PythonOperator): Read_dataset_files> dag:<DAG: Read_data_and_move_data> dagrun:<DagRun Read_data_and_move_data @ 2024-09-20 22:50:00+00:00: scheduled__2024-09-20T22:50:00+00:00, state:running, queued_at: 2024-09-20 23:00:27.500932+00:00. externally triggered: False>
[2024-09-20T23:00:45.753+0000] {logging_mixin.py:190} INFO - Failure caused by No files in the folder
[2024-09-20T23:00:45.753+0000] {taskinstance.py:1225} INFO - Marking task as FAILED. dag_id=Read_data_and_move_data, task_id=Read_dataset_files, run_id=scheduled__2024-09-20T22:50:00+00:00, execution_date=20240920T225000, start_date=20240920T230045, end_date=20240920T230045
[2024-09-20T23:00:45.799+0000] {taskinstance.py:340} INFO - ::group::Post task execution logs
[2024-09-20T23:00:45.805+0000] {standard_task_runner.py:124} ERROR - Failed to execute job 75 for task Read_dataset_files (No files in the folder; 62)
Traceback (most recent call last):
  File "/home/airflow/.local/lib/python3.12/site-packages/airflow/task/task_runner/standard_task_runner.py", line 117, in _start_by_fork
    ret = args.func(args, dag=self.dag)
          ^^^^^^^^^^^^^^^^^^^^^^^^^^^^^
  File "/home/airflow/.local/lib/python3.12/site-packages/airflow/cli/cli_config.py", line 49, in command
    return func(*args, **kwargs)
           ^^^^^^^^^^^^^^^^^^^^^
  File "/home/airflow/.local/lib/python3.12/site-packages/airflow/utils/cli.py", line 115, in wrapper
    return f(*args, **kwargs)
           ^^^^^^^^^^^^^^^^^^
  File "/home/airflow/.local/lib/python3.12/site-packages/airflow/cli/commands/task_command.py", line 483, in task_run
    task_return_code = _run_task_by_selected_method(args, _dag, ti)
                       ^^^^^^^^^^^^^^^^^^^^^^^^^^^^^^^^^^^^^^^^^^^^
  File "/home/airflow/.local/lib/python3.12/site-packages/airflow/cli/commands/task_command.py", line 256, in _run_task_by_selected_method
    return _run_raw_task(args, ti)
           ^^^^^^^^^^^^^^^^^^^^^^^
  File "/home/airflow/.local/lib/python3.12/site-packages/airflow/cli/commands/task_command.py", line 341, in _run_raw_task
    return ti._run_raw_task(
           ^^^^^^^^^^^^^^^^^
  File "/home/airflow/.local/lib/python3.12/site-packages/airflow/utils/session.py", line 97, in wrapper
    return func(*args, session=session, **kwargs)
           ^^^^^^^^^^^^^^^^^^^^^^^^^^^^^^^^^^^^^^
  File "/home/airflow/.local/lib/python3.12/site-packages/airflow/models/taskinstance.py", line 3004, in _run_raw_task
    return _run_raw_task(
           ^^^^^^^^^^^^^^
  File "/home/airflow/.local/lib/python3.12/site-packages/airflow/models/taskinstance.py", line 273, in _run_raw_task
    TaskInstance._execute_task_with_callbacks(
  File "/home/airflow/.local/lib/python3.12/site-packages/airflow/models/taskinstance.py", line 3158, in _execute_task_with_callbacks
    result = self._execute_task(context, task_orig)
             ^^^^^^^^^^^^^^^^^^^^^^^^^^^^^^^^^^^^^^
  File "/home/airflow/.local/lib/python3.12/site-packages/airflow/models/taskinstance.py", line 3182, in _execute_task
    return _execute_task(self, context, task_orig)
           ^^^^^^^^^^^^^^^^^^^^^^^^^^^^^^^^^^^^^^^
  File "/home/airflow/.local/lib/python3.12/site-packages/airflow/models/taskinstance.py", line 767, in _execute_task
    result = _execute_callable(context=context, **execute_callable_kwargs)
             ^^^^^^^^^^^^^^^^^^^^^^^^^^^^^^^^^^^^^^^^^^^^^^^^^^^^^^^^^^^^^
  File "/home/airflow/.local/lib/python3.12/site-packages/airflow/models/taskinstance.py", line 733, in _execute_callable
    return ExecutionCallableRunner(
           ^^^^^^^^^^^^^^^^^^^^^^^^
  File "/home/airflow/.local/lib/python3.12/site-packages/airflow/utils/operator_helpers.py", line 252, in run
    return self.func(*args, **kwargs)
           ^^^^^^^^^^^^^^^^^^^^^^^^^^
  File "/home/airflow/.local/lib/python3.12/site-packages/airflow/models/baseoperator.py", line 406, in wrapper
    return func(self, *args, **kwargs)
           ^^^^^^^^^^^^^^^^^^^^^^^^^^^
  File "/home/airflow/.local/lib/python3.12/site-packages/airflow/operators/python.py", line 238, in execute
    return_value = self.execute_callable()
                   ^^^^^^^^^^^^^^^^^^^^^^^
  File "/home/airflow/.local/lib/python3.12/site-packages/airflow/operators/python.py", line 256, in execute_callable
    return runner.run(*self.op_args, **self.op_kwargs)
           ^^^^^^^^^^^^^^^^^^^^^^^^^^^^^^^^^^^^^^^^^^^
  File "/home/airflow/.local/lib/python3.12/site-packages/airflow/utils/operator_helpers.py", line 252, in run
    return self.func(*args, **kwargs)
           ^^^^^^^^^^^^^^^^^^^^^^^^^^
  File "/opt/airflow/dags/data_ingestion.py", line 14, in read_data
    raise ValueError("No files in the folder")
ValueError: No files in the folder
[2024-09-20T23:00:45.862+0000] {local_task_job_runner.py:266} INFO - Task exited with return code 1
[2024-09-20T23:00:45.874+0000] {local_task_job_runner.py:245} INFO - ::endgroup::
